Workbook

Sheet README
A1: Third-Party & Vendor Risk Management Program Workbook
A2: Vendor assessment package for an organization using cloud providers and AI software vendors. Sample organization: Meridian Analytics Group (fictional); all vendors and data are fictional.
A4: Purpose | B4: Provides a complete, reusable vendor risk assessment package: questionnaire, inherent and residual risk scoring, due diligence checklist, vendor risk register, approval workflow and monitoring schedule. Aligned to ISO/IEC 27001:2022 (Annex A.5.19–A.5.23), ISO/IEC 42001:2023, NIST CSF 2.0 (GV.SC) and NIST AI RMF.
A5: How to use | B5: 1. Review and adjust scoring parameters in Methodology (weights, thresholds, cadence) to match your risk appetite. 2. Add each vendor in Vendor_Register and score the six inherent risk factors (1–5). 3. Send the Questionnaire; record the vendor's answers in that vendor's column. 4. Work through Due_Diligence for the vendor (select the Vendor ID in cell B3). 5. Review Assessment_Results and the recommended decision in Vendor_Register. 6. Log individual risks and treatment plans in Risk_Register. 7. Obtain approval per Approval_Workflow and set the review dates in Monitoring.
A6: Colour legend | B6: Blue text on a pale yellow fill = input cell you may edit. Black text = formula (do not overwrite). Rating colours: green = Low, yellow = Medium, orange = High, dark red = Critical.
A7: Sheets | B7: Dashboard – portfolio summary and heat map Vendor_Register – inventory, inherent and residual scoring, decision, review dates Methodology – all weights, thresholds and assumptions Questionnaire – 51 weighted control questions (incl. 8 AI-specific), 7 critical controls Assessment_Results – control effectiveness by vendor and domain Due_Diligence – 34-item checklist (general, cloud and AI) Risk_Register – 5×5 scored vendor risks with treatment Approval_Workflow – 10-stage workflow, authority matrix, exception rules Monitoring – cadence by tier, calculated review calendar, triggers
A8: Sample data | B8: Six fictional vendors (two cloud infrastructure/backup, one SaaS CRM, one survey tool, two AI platforms) demonstrate every rating band, a critical control gap, an overdue reassessment and an expired attestation. Delete or overwrite them before real use. Capacity: 10 vendors in the register and questionnaire, 30 risks in Risk_Register.
A9: Assumptions & limits | B9: Weights, thresholds, the 70% maximum risk reduction and the impact scale are illustrative defaults, not regulatory requirements; calibrate them to the organization. Standard control mappings are indicative and should be validated against the published standards. The assessment as-of date is set in Methodology!B4 (use =TODAY() for live tracking).
A10: Confidentiality | B10: Never store real vendor questionnaires, contracts, credentials or client data in a public repository.
A11: Version | B11: v1.0 | Created October 2026 | Author: Saad Ali

Sheet Dashboard
A1: Third-Party Risk Dashboard
A2: Sample organization: Meridian Analytics Group (fictional). All figures calculate from the other sheets.
A3: Key indicators
A4: Vendors in register | B4: =SUMPRODUCT(--(Vendor_Register!A6:A15<>"")) -> 6
A5: Average inherent risk score | B5: =IFERROR(AVERAGE(Vendor_Register!L6:L15),"") -> 63
A6: Average control effectiveness | B6: =IFERROR(AVERAGE(Vendor_Register!N6:N15),"") -> 0.76250701
A7: Vendors with critical control gaps | B7: =COUNTIF(Vendor_Register!O6:O15,">0") -> 1
A8: Reassessments overdue | B8: =COUNTIF(Vendor_Register!X6:X15,"Overdue") -> 1
A9: Open vendor risks (open or in progress) | B9: =COUNTIF(Risk_Register!S6:S35,"Open")+COUNTIF(Risk_Register!S6:S35,"In Progress") -> 10
A10: High or Critical residual risks (open items) | B10: =SUMPRODUCT(((Risk_Register!N6:N35="High")+(Risk_Register!N6:N35="Critical"))*((Risk_Register!S6:S35="Open")+(Risk_Register!S6:S35="In Progress"))) -> 1
A12: Risk rating distribution (vendors)
A13: Rating | B13: Inherent | C13: Residual
A14: Low | B14: =COUNTIF(Vendor_Register!M6:M15,A14) -> 1 | C14: =COUNTIF(Vendor_Register!Q6:Q15,A14) -> 3
A15: Medium | B15: =COUNTIF(Vendor_Register!M6:M15,A15) -> 1 | C15: =COUNTIF(Vendor_Register!Q6:Q15,A15) -> 2
A16: High | B16: =COUNTIF(Vendor_Register!M6:M15,A16) -> 3 | C16: =COUNTIF(Vendor_Register!Q6:Q15,A16) -> 1
A17: Critical | B17: =COUNTIF(Vendor_Register!M6:M15,A17) -> 1 | C17: =COUNTIF(Vendor_Register!Q6:Q15,A17) -> 0
A19: Approval status
A20: Status | B20: Vendors
A21: Prospective | B21: =COUNTIF(Vendor_Register!T6:T15,A21) -> 0
A22: Under Review | B22: =COUNTIF(Vendor_Register!T6:T15,A22) -> 1
A23: Approved | B23: =COUNTIF(Vendor_Register!T6:T15,A23) -> 4
A24: Conditionally Approved | B24: =COUNTIF(Vendor_Register!T6:T15,A24) -> 1
A25: Rejected | B25: =COUNTIF(Vendor_Register!T6:T15,A25) -> 0
A26: Offboarded | B26: =COUNTIF(Vendor_Register!T6:T15,A26) -> 0
A28: Residual risk heat map (Risk_Register: count of risks)
A29: Impact ↓ / Likelihood → | B29: 1 | C29: 2 | D29: 3 | E29: 4 | F29: 5
A30: 5 | B30: =COUNTIFS(Risk_Register!$K$6:$K$35,1,Risk_Register!$L$6:$L$35,5,Risk_Register!$S$6:$S$35,"<>Closed") -> 0 | C30: =COUNTIFS(Risk_Register!$K$6:$K$35,2,Risk_Register!$L$6:$L$35,5,Risk_Register!$S$6:$S$35,"<>Closed") -> 1 | D30: =COUNTIFS(Risk_Register!$K$6:$K$35,3,Risk_Register!$L$6:$L$35,5,Risk_Register!$S$6:$S$35,"<>Closed") -> 0 | E30: =COUNTIFS(Risk_Register!$K$6:$K$35,4,Risk_Register!$L$6:$L$35,5,Risk_Register!$S$6:$S$35,"<>Closed") -> 0 | F30: =COUNTIFS(Risk_Register!$K$6:$K$35,5,Risk_Register!$L$6:$L$35,5,Risk_Register!$S$6:$S$35,"<>Closed") -> 0
A31: 4 | B31: =COUNTIFS(Risk_Register!$K$6:$K$35,1,Risk_Register!$L$6:$L$35,4,Risk_Register!$S$6:$S$35,"<>Closed") -> 1 | C31: =COUNTIFS(Risk_Register!$K$6:$K$35,2,Risk_Register!$L$6:$L$35,4,Risk_Register!$S$6:$S$35,"<>Closed") -> 3 | D31: =COUNTIFS(Risk_Register!$K$6:$K$35,3,Risk_Register!$L$6:$L$35,4,Risk_Register!$S$6:$S$35,"<>Closed") -> 0 | E31: =COUNTIFS(Risk_Register!$K$6:$K$35,4,Risk_Register!$L$6:$L$35,4,Risk_Register!$S$6:$S$35,"<>Closed") -> 0 | F31: =COUNTIFS(Risk_Register!$K$6:$K$35,5,Risk_Register!$L$6:$L$35,4,Risk_Register!$S$6:$S$35,"<>Closed") -> 0
A32: 3 | B32: =COUNTIFS(Risk_Register!$K$6:$K$35,1,Risk_Register!$L$6:$L$35,3,Risk_Register!$S$6:$S$35,"<>Closed") -> 0 | C32: =COUNTIFS(Risk_Register!$K$6:$K$35,2,Risk_Register!$L$6:$L$35,3,Risk_Register!$S$6:$S$35,"<>Closed") -> 3 | D32: =COUNTIFS(Risk_Register!$K$6:$K$35,3,Risk_Register!$L$6:$L$35,3,Risk_Register!$S$6:$S$35,"<>Closed") -> 3 | E32: =COUNTIFS(Risk_Register!$K$6:$K$35,4,Risk_Register!$L$6:$L$35,3,Risk_Register!$S$6:$S$35,"<>Closed") -> 0 | F32: =COUNTIFS(Risk_Register!$K$6:$K$35,5,Risk_Register!$L$6:$L$35,3,Risk_Register!$S$6:$S$35,"<>Closed") -> 0
A33: 2 | B33: =COUNTIFS(Risk_Register!$K$6:$K$35,1,Risk_Register!$L$6:$L$35,2,Risk_Register!$S$6:$S$35,"<>Closed") -> 0 | C33: =COUNTIFS(Risk_Register!$K$6:$K$35,2,Risk_Register!$L$6:$L$35,2,Risk_Register!$S$6:$S$35,"<>Closed") -> 1 | D33: =COUNTIFS(Risk_Register!$K$6:$K$35,3,Risk_Register!$L$6:$L$35,2,Risk_Register!$S$6:$S$35,"<>Closed") -> 0 | E33: =COUNTIFS(Risk_Register!$K$6:$K$35,4,Risk_Register!$L$6:$L$35,2,Risk_Register!$S$6:$S$35,"<>Closed") -> 0 | F33: =COUNTIFS(Risk_Register!$K$6:$K$35,5,Risk_Register!$L$6:$L$35,2,Risk_Register!$S$6:$S$35,"<>Closed") -> 0
A34: 1 | B34: =COUNTIFS(Risk_Register!$K$6:$K$35,1,Risk_Register!$L$6:$L$35,1,Risk_Register!$S$6:$S$35,"<>Closed") -> 0 | C34: =COUNTIFS(Risk_Register!$K$6:$K$35,2,Risk_Register!$L$6:$L$35,1,Risk_Register!$S$6:$S$35,"<>Closed") -> 0 | D34: =COUNTIFS(Risk_Register!$K$6:$K$35,3,Risk_Register!$L$6:$L$35,1,Risk_Register!$S$6:$S$35,"<>Closed") -> 0 | E34: =COUNTIFS(Risk_Register!$K$6:$K$35,4,Risk_Register!$L$6:$L$35,1,Risk_Register!$S$6:$S$35,"<>Closed") -> 0 | F34: =COUNTIFS(Risk_Register!$K$6:$K$35,5,Risk_Register!$L$6:$L$35,1,Risk_Register!$S$6:$S$35,"<>Closed") -> 0
A36: Vendor snapshot
A37: Vendor | B37: Inherent | C37: Control effectiveness | D37: Residual | E37: Recommended decision
A38: =IF(Vendor_Register!A6="","",Vendor_Register!B6) -> Stratus Cloud Infrastructure | B38: =IF(Vendor_Register!A6="","",Vendor_Register!M6) -> Critical | C38: =IF(Vendor_Register!A6="","",Vendor_Register!N6) -> 0.96153846 | D38: =IF(Vendor_Register!A6="","",Vendor_Register!Q6) -> Medium | E38: =IF(Vendor_Register!A6="","",Vendor_Register!R6) -> Approve with standard monitoring
A39: =IF(Vendor_Register!A7="","",Vendor_Register!B7) -> NimbusAI Language Platform | B39: =IF(Vendor_Register!A7="","",Vendor_Register!M7) -> High | C39: =IF(Vendor_Register!A7="","",Vendor_Register!N7) -> 0.81531532 | D39: =IF(Vendor_Register!A7="","",Vendor_Register!Q7) -> Medium | E39: =IF(Vendor_Register!A7="","",Vendor_Register!R7) -> Remediate critical gaps before approval
A40: =IF(Vendor_Register!A8="","",Vendor_Register!B8) -> Orbit CRM Suite | B40: =IF(Vendor_Register!A8="","",Vendor_Register!M8) -> High | C40: =IF(Vendor_Register!A8="","",Vendor_Register!N8) -> 0.51098901 | D40: =IF(Vendor_Register!A8="","",Vendor_Register!Q8) -> High | E40: =IF(Vendor_Register!A8="","",Vendor_Register!R8) -> Conditional approval with remediation plan
A41: =IF(Vendor_Register!A9="","",Vendor_Register!B9) -> InsightML Analytics | B41: =IF(Vendor_Register!A9="","",Vendor_Register!M9) -> Medium | C41: =IF(Vendor_Register!A9="","",Vendor_Register!N9) -> 0.74324324 | D41: =IF(Vendor_Register!A9="","",Vendor_Register!Q9) -> Low | E41: =IF(Vendor_Register!A9="","",Vendor_Register!R9) -> Approve
A42: =IF(Vendor_Register!A10="","",Vendor_Register!B10) -> Cirrus Backup & Recovery | B42: =IF(Vendor_Register!A10="","",Vendor_Register!M10) -> High | C42: =IF(Vendor_Register!A10="","",Vendor_Register!N10) -> 0.95604396 | D42: =IF(Vendor_Register!A10="","",Vendor_Register!Q10) -> Low | E42: =IF(Vendor_Register!A10="","",Vendor_Register!R10) -> Approve
A43: =IF(Vendor_Register!A11="","",Vendor_Register!B11) -> Brightleaf Survey Tool | B43: =IF(Vendor_Register!A11="","",Vendor_Register!M11) -> Low | C43: =IF(Vendor_Register!A11="","",Vendor_Register!N11) -> 0.58791209 | D43: =IF(Vendor_Register!A11="","",Vendor_Register!Q11) -> Low | E43: =IF(Vendor_Register!A11="","",Vendor_Register!R11) -> Approve
A44: =IF(Vendor_Register!A12="","",Vendor_Register!B12) | B44: =IF(Vendor_Register!A12="","",Vendor_Register!M12) | C44: =IF(Vendor_Register!A12="","",Vendor_Register!N12) | D44: =IF(Vendor_Register!A12="","",Vendor_Register!Q12) | E44: =IF(Vendor_Register!A12="","",Vendor_Register!R12)
...

Sheet Vendor_Register
A1: Vendor Register – Inherent & Residual Risk
A2: Sample organization: Meridian Analytics Group (fictional). Vendors are fictional. Enter the 6 factor scores (1–5); everything else calculates.
A5: Vendor ID | B5: Vendor name | C5: Service provided | D5: Category | E5: Business owner | F5: Data sensitivity (1–5) | G5: Business criticality (1–5) | H5: System / network access (1–5) | I5: Regulatory exposure (1–5) | J5: Substitutability (1–5) | K5: AI impact (1–5) | L5: Inherent score (20–100) | M5: Inherent rating | N5: Control effectiveness | O5: Critical gaps | P5: Residual score | Q5: Residual rating | R5: Recommended decision | S5: Required approver | T5: Approval status | U5: Last assessment | V5: Review cycle (months) | W5: Next review due | X5: Review status | Y5: Contract renewal | Z5: Notes
A6: V-001 | B6: Stratus Cloud Infrastructure | C6: IaaS/PaaS hosting for production workloads and databases | D6: Cloud Infrastructure (IaaS/PaaS) | E6: Head of Infrastructure | F6: 5 | G6: 5 | H6: 5 | I6: 4 | J6: 4 | K6: 1 | L6: =IF($A6="","",ROUND((F6*Methodology!$B$10+G6*Methodology!$B$11+H6*Methodology!$B$12+I6*Methodology!$B$13+J6*Methodology!$B$14+K6*Methodology!$B$15)/Methodology!$B$16*Methodology!$B$6,1)) -> 88 | M6: =IF($A6="","",INDEX(Methodology!$A$20:$A$23,MATCH(L6,Methodology!$B$20:$B$23,1))) -> Critical | N6: =IF($A6="","",IFERROR(INDEX(Assessment_Results!$C$6:$C$15,MATCH($A6,Assessment_Results!$A$6:$A$15,0)),"")) -> 0.96153846 | O6: =IF($A6="","",IFERROR(INDEX(Assessment_Results!$E$6:$E$15,MATCH($A6,Assessment_Results!$A$6:$A$15,0)),"")) -> 0 | P6: =IF(OR($A6="",N6=""),"",ROUND(L6*(1-N6*Methodology!$B$5),1)) -> 28.8 | Q6: =IF(P6="","",INDEX(Methodology!$A$20:$A$23,MATCH(P6,Methodology!$C$20:$C$23,1))) -> Medium | R6: =IF($A6="","",IF(N6="","Assessment pending",IF(O6>0,"Remediate critical gaps before approval",IF(Q6="Critical","Escalate: executive risk acceptance required",IF(Q6="High","Conditional approval with remediation plan",IF(Q6="Medium","Approve with standard monitoring","Approve")))))) -> Approve with standard monitoring | S6: =IF($A6="","",IF(Q6="","Pending assessment",INDEX(Approval_Workflow!$B$20:$B$23,MATCH(Q6,Approval_Workflow!$A$20:$A$23,0)))) -> Business Owner + Information Security Manager | T6: Approved | U6: 46093 | V6: =IF($A6="","",INDEX(Methodology!$D$20:$D$23,MATCH(M6,Methodology!$A$20:$A$23,0))) -> 12 | W6: =IF(OR($A6="",U6=""),"",EDATE(U6,V6)) -> 46458 | X6: =IF(W6="","",IF(W6<Methodology!$B$4,"Overdue",IF(W6-Methodology!$B$4<=90,"Due within 90 days","On schedule"))) -> On schedule | Y6: 46568
A7: V-002 | B7: NimbusAI Language Platform | C7: Hosted large-language-model API embedded in the customer support assistant | D7: AI/ML Software | E7: Director of Customer Support | F7: 5 | G7: 3 | H7: 3 | I7: 4 | J7: 2 | K7: 5 | L7: =IF($A7="","",ROUND((F7*Methodology!$B$10+G7*Methodology!$B$11+H7*Methodology!$B$12+I7*Methodology!$B$13+J7*Methodology!$B$14+K7*Methodology!$B$15)/Methodology!$B$16*Methodology!$B$6,1)) -> 76 | M7: =IF($A7="","",INDEX(Methodology!$A$20:$A$23,MATCH(L7,Methodology!$B$20:$B$23,1))) -> High | N7: =IF($A7="","",IFERROR(INDEX(Assessment_Results!$C$6:$C$15,MATCH($A7,Assessment_Results!$A$6:$A$15,0)),"")) -> 0.81531532 | O7: =IF($A7="","",IFERROR(INDEX(Assessment_Results!$E$6:$E$15,MATCH($A7,Assessment_Results!$A$6:$A$15,0)),"")) -> 1 | P7: =IF(OR($A7="",N7=""),"",ROUND(L7*(1-N7*Methodology!$B$5),1)) -> 32.6 | Q7: =IF(P7="","",INDEX(Methodology!$A$20:$A$23,MATCH(P7,Methodology!$C$20:$C$23,1))) -> Medium | R7: =IF($A7="","",IF(N7="","Assessment pending",IF(O7>0,"Remediate critical gaps before approval",IF(Q7="Critical","Escalate: executive risk acceptance required",IF(Q7="High","Conditional approval with remediation plan",IF(Q7="Medium","Approve with standard monitoring","Approve")))))) -> Remediate critical gaps before approval | S7: =IF($A7="","",IF(Q7="","Pending assessment",INDEX(Approval_Workflow!$B$20:$B$23,MATCH(Q7,Approval_Workflow!$A$20:$A$23,0)))) -> Business Owner + Information Security Manager | T7: Under Review | V7: =IF($A7="","",INDEX(Methodology!$D$20:$D$23,MATCH(M7,Methodology!$A$20:$A$23,0))) -> 18 | W7: =IF(OR($A7="",U7=""),"",EDATE(U7,V7)) | X7: =IF(W7="","",IF(W7<Methodology!$B$4,"Overdue",IF(W7-Methodology!$B$4<=90,"Due within 90 days","On schedule"))) | Y7: 46675 | Z7: Pending approval: critical gap on AI data-use commitment (see Risk_Register VR-004).
A8: V-003 | B8: Orbit CRM Suite | C8: SaaS CRM storing customer contact and contract data | D8: SaaS Application | E8: VP Sales | F8: 4 | G8: 4 | H8: 3 | I8: 3 | J8: 3 | K8: 1 | L8: =IF($A8="","",ROUND((F8*Methodology!$B$10+G8*Methodology!$B$11+H8*Methodology!$B$12+I8*Methodology!$B$13+J8*Methodology!$B$14+K8*Methodology!$B$15)/Methodology!$B$16*Methodology!$B$6,1)) -> 67 | M8: =IF($A8="","",INDEX(Methodology!$A$20:$A$23,MATCH(L8,Methodology!$B$20:$B$23,1))) -> High | N8: =IF($A8="","",IFERROR(INDEX(Assessment_Results!$C$6:$C$15,MATCH($A8,Assessment_Results!$A$6:$A$15,0)),"")) -> 0.51098901 | O8: =IF($A8="","",IFERROR(INDEX(Assessment_Results!$E$6:$E$15,MATCH($A8,Assessment_Results!$A$6:$A$15,0)),"")) -> 0 | P8: =IF(OR($A8="",N8=""),"",ROUND(L8*(1-N8*Methodology!$B$5),1)) -> 43 | Q8: =IF(P8="","",INDEX(Methodology!$A$20:$A$23,MATCH(P8,Methodology!$C$20:$C$23,1))) -> High | R8: =IF($A8="","",IF(N8="","Assessment pending",IF(O8>0,"Remediate critical gaps before approval",IF(Q8="Critical","Escalate: executive risk acceptance required",IF(Q8="High","Conditional approval with remediation plan",IF(Q8="Medium","Approve with standard monitoring","Approve")))))) -> Conditional approval with remediation plan | S8: =IF($A8="","",IF(Q8="","Pending assessment",INDEX(Approval_Workflow!$B$20:$B$23,MATCH(Q8,Approval_Workflow!$A$20:$A$23,0)))) -> Information Security Manager + Privacy/Legal + Head of Business Unit | T8: Conditionally Approved | U8: 45920 | V8: =IF($A8="","",INDEX(Methodology!$D$20:$D$23,MATCH(M8,Methodology!$A$20:$A$23,0))) -> 18 | W8: =IF(OR($A8="",U8=""),"",EDATE(U8,V8)) -> 46466 | X8: =IF(W8="","",IF(W8<Methodology!$B$4,"Overdue",IF(W8-Methodology!$B$4<=90,"Due within 90 days","On schedule"))) -> On schedule | Y8: 46630 | Z8: Attestation expired; remediation plan agreed with vendor.
A9: V-004 | B9: InsightML Analytics | C9: AI-driven usage analytics and churn-prediction service | D9: AI/ML Software | E9: Head of Data Science | F9: 3 | G9: 2 | H9: 2 | I9: 2 | J9: 2 | K9: 4 | L9: =IF($A9="","",ROUND((F9*Methodology!$B$10+G9*Methodology!$B$11+H9*Methodology!$B$12+I9*Methodology!$B$13+J9*Methodology!$B$14+K9*Methodology!$B$15)/Methodology!$B$16*Methodology!$B$6,1)) -> 50 | M9: =IF($A9="","",INDEX(Methodology!$A$20:$A$23,MATCH(L9,Methodology!$B$20:$B$23,1))) -> Medium | N9: =IF($A9="","",IFERROR(INDEX(Assessment_Results!$C$6:$C$15,MATCH($A9,Assessment_Results!$A$6:$A$15,0)),"")) -> 0.74324324 | O9: =IF($A9="","",IFERROR(INDEX(Assessment_Results!$E$6:$E$15,MATCH($A9,Assessment_Results!$A$6:$A$15,0)),"")) -> 0 | P9: =IF(OR($A9="",N9=""),"",ROUND(L9*(1-N9*Methodology!$B$5),1)) -> 24 | Q9: =IF(P9="","",INDEX(Methodology!$A$20:$A$23,MATCH(P9,Methodology!$C$20:$C$23,1))) -> Low | R9: =IF($A9="","",IF(N9="","Assessment pending",IF(O9>0,"Remediate critical gaps before approval",IF(Q9="Critical","Escalate: executive risk acceptance required",IF(Q9="High","Conditional approval with remediation plan",IF(Q9="Medium","Approve with standard monitoring","Approve")))))) -> Approve | S9: =IF($A9="","",IF(Q9="","Pending assessment",INDEX(Approval_Workflow!$B$20:$B$23,MATCH(Q9,Approval_Workflow!$A$20:$A$23,0)))) -> Business Owner + GRC Analyst | T9: Approved | U9: 45519 | V9: =IF($A9="","",INDEX(Methodology!$D$20:$D$23,MATCH(M9,Methodology!$A$20:$A$23,0))) -> 24 | W9: =IF(OR($A9="",U9=""),"",EDATE(U9,V9)) -> 46249 | X9: =IF(W9="","",IF(W9<Methodology!$B$4,"Overdue",IF(W9-Methodology!$B$4<=90,"Due within 90 days","On schedule"))) -> Overdue | Y9: 46507 | Z9: Full reassessment overdue; scheduled for Q4.
A10: V-005 | B10: Cirrus Backup & Recovery | C10: Cloud backup and disaster-recovery service | D10: SaaS Application | E10: IT Operations Manager | F10: 4 | G10: 4 | H10: 2 | I10: 3 | J10: 3 | K10: 1 | L10: =IF($A10="","",ROUND((F10*Methodology!$B$10+G10*Methodology!$B$11+H10*Methodology!$B$12+I10*Methodology!$B$13+J10*Methodology!$B$14+K10*Methodology!$B$15)/Methodology!$B$16*Methodology!$B$6,1)) -> 64 | M10: =IF($A10="","",INDEX(Methodology!$A$20:$A$23,MATCH(L10,Methodology!$B$20:$B$23,1))) -> High | N10: =IF($A10="","",IFERROR(INDEX(Assessment_Results!$C$6:$C$15,MATCH($A10,Assessment_Results!$A$6:$A$15,0)),"")) -> 0.95604396 | O10: =IF($A10="","",IFERROR(INDEX(Assessment_Results!$E$6:$E$15,MATCH($A10,Assessment_Results!$A$6:$A$15,0)),"")) -> 0 | P10: =IF(OR($A10="",N10=""),"",ROUND(L10*(1-N10*Methodology!$B$5),1)) -> 21.2 | Q10: =IF(P10="","",INDEX(Methodology!$A$20:$A$23,MATCH(P10,Methodology!$C$20:$C$23,1))) -> Low | R10: =IF($A10="","",IF(N10="","Assessment pending",IF(O10>0,"Remediate critical gaps before approval",IF(Q10="Critical","Escalate: executive risk acceptance required",IF(Q10="High","Conditional approval with remediation plan",IF(Q10="Medium","Approve with standard monitoring","Approve")))))) -> Approve | S10: =IF($A10="","",IF(Q10="","Pending assessment",INDEX(Approval_Workflow!$B$20:$B$23,MATCH(Q10,Approval_Workflow!$A$20:$A$23,0)))) -> Business Owner + GRC Analyst | T10: Approved | U10: 45782 | V10: =IF($A10="","",INDEX(Methodology!$D$20:$D$23,MATCH(M10,Methodology!$A$20:$A$23,0))) -> 18 | W10: =IF(OR($A10="",U10=""),"",EDATE(U10,V10)) -> 46331 | X10: =IF(W10="","",IF(W10<Methodology!$B$4,"Overdue",IF(W10-Methodology!$B$4<=90,"Due within 90 days","On schedule"))) -> Due within 90 days | Y10: 46538
A11: V-006 | B11: Brightleaf Survey Tool | C11: Online survey platform for employee and customer feedback | D11: SaaS Application | E11: Marketing Manager | F11: 2 | G11: 2 | H11: 1 | I11: 2 | J11: 1 | K11: 1 | L11: =IF($A11="","",ROUND((F11*Methodology!$B$10+G11*Methodology!$B$11+H11*Methodology!$B$12+I11*Methodology!$B$13+J11*Methodology!$B$14+K11*Methodology!$B$15)/Methodology!$B$16*Methodology!$B$6,1)) -> 33 | M11: =IF($A11="","",INDEX(Methodology!$A$20:$A$23,MATCH(L11,Methodology!$B$20:$B$23,1))) -> Low | N11: =IF($A11="","",IFERROR(INDEX(Assessment_Results!$C$6:$C$15,MATCH($A11,Assessment_Results!$A$6:$A$15,0)),"")) -> 0.58791209 | O11: =IF($A11="","",IFERROR(INDEX(Assessment_Results!$E$6:$E$15,MATCH($A11,Assessment_Results!$A$6:$A$15,0)),"")) -> 0 | P11: =IF(OR($A11="",N11=""),"",ROUND(L11*(1-N11*Methodology!$B$5),1)) -> 19.4 | Q11: =IF(P11="","",INDEX(Methodology!$A$20:$A$23,MATCH(P11,Methodology!$C$20:$C$23,1))) -> Low | R11: =IF($A11="","",IF(N11="","Assessment pending",IF(O11>0,"Remediate critical gaps before approval",IF(Q11="Critical","Escalate: executive risk acceptance required",IF(Q11="High","Conditional approval with remediation plan",IF(Q11="Medium","Approve with standard monitoring","Approve")))))) -> Approve | S11: =IF($A11="","",IF(Q11="","Pending assessment",INDEX(Approval_Workflow!$B$20:$B$23,MATCH(Q11,Approval_Workflow!$A$20:$A$23,0)))) -> Business Owner + GRC Analyst | T11: Approved | U11: 45323 | V11: =IF($A11="","",INDEX(Methodology!$D$20:$D$23,MATCH(M11,Methodology!$A$20:$A$23,0))) -> 36 | W11: =IF(OR($A11="",U11=""),"",EDATE(U11,V11)) -> 46419 | X11: =IF(W11="","",IF(W11<Methodology!$B$4,"Overdue",IF(W11-Methodology!$B$4<=90,"Due within 90 days","On schedule"))) -> On schedule | Y11: 46477
L12: =IF($A12="","",ROUND((F12*Methodology!$B$10+G12*Methodology!$B$11+H12*Methodology!$B$12+I12*Methodology!$B$13+J12*Methodology!$B$14+K12*Methodology!$B$15)/Methodology!$B$16*Methodology!$B$6,1)) | M12: =IF($A12="","",INDEX(Methodology!$A$20:$A$23,MATCH(L12,Methodology!$B$20:$B$23,1))) | N12: =IF($A12="","",IFERROR(INDEX(Assessment_Results!$C$6:$C$15,MATCH($A12,Assessment_Results!$A$6:$A$15,0)),"")) | O12: =IF($A12="","",IFERROR(INDEX(Assessment_Results!$E$6:$E$15,MATCH($A12,Assessment_Results!$A$6:$A$15,0)),"")) | P12: =IF(OR($A12="",N12=""),"",ROUND(L12*(1-N12*Methodology!$B$5),1)) | Q12: =IF(P12="","",INDEX(Methodology!$A$20:$A$23,MATCH(P12,Methodology!$C$20:$C$23,1))) | R12: =IF($A12="","",IF(N12="","Assessment pending",IF(O12>0,"Remediate critical gaps before approval",IF(Q12="Critical","Escalate: executive risk acceptance required",IF(Q12="High","Conditional approval with remediation plan",IF(Q12="Medium","Approve with standard monitoring","Approve")))))) | S12: =IF($A12="","",IF(Q12="","Pending assessment",INDEX(Approval_Workflow!$B$20:$B$23,MATCH(Q12,Approval_Workflow!$A$20:$A$23,0)))) | V12: =IF($A12="","",INDEX(Methodology!$D$20:$D$23,MATCH(M12,Methodology!$A$20:$A$23,0))) | W12: =IF(OR($A12="",U12=""),"",EDATE(U12,V12)) | X12: =IF(W12="","",IF(W12<Methodology!$B$4,"Overdue",IF(W12-Methodology!$B$4<=90,"Due within 90 days","On schedule")))
L13: =IF($A13="","",ROUND((F13*Methodology!$B$10+G13*Methodology!$B$11+H13*Methodology!$B$12+I13*Methodology!$B$13+J13*Methodology!$B$14+K13*Methodology!$B$15)/Methodology!$B$16*Methodology!$B$6,1)) | M13: =IF($A13="","",INDEX(Methodology!$A$20:$A$23,MATCH(L13,Methodology!$B$20:$B$23,1))) | N13: =IF($A13="","",IFERROR(INDEX(Assessment_Results!$C$6:$C$15,MATCH($A13,Assessment_Results!$A$6:$A$15,0)),"")) | O13: =IF($A13="","",IFERROR(INDEX(Assessment_Results!$E$6:$E$15,MATCH($A13,Assessment_Results!$A$6:$A$15,0)),"")) | P13: =IF(OR($A13="",N13=""),"",ROUND(L13*(1-N13*Methodology!$B$5),1)) | Q13: =IF(P13="","",INDEX(Methodology!$A$20:$A$23,MATCH(P13,Methodology!$C$20:$C$23,1))) | R13: =IF($A13="","",IF(N13="","Assessment pending",IF(O13>0,"Remediate critical gaps before approval",IF(Q13="Critical","Escalate: executive risk acceptance required",IF(Q13="High","Conditional approval with remediation plan",IF(Q13="Medium","Approve with standard monitoring","Approve")))))) | S13: =IF($A13="","",IF(Q13="","Pending assessment",INDEX(Approval_Workflow!$B$20:$B$23,MATCH(Q13,Approval_Workflow!$A$20:$A$23,0)))) | V13: =IF($A13="","",INDEX(Methodology!$D$20:$D$23,MATCH(M13,Methodology!$A$20:$A$23,0))) | W13: =IF(OR($A13="",U13=""),"",EDATE(U13,V13)) | X13: =IF(W13="","",IF(W13<Methodology!$B$4,"Overdue",IF(W13-Methodology!$B$4<=90,"Due within 90 days","On schedule")))
L14: =IF($A14="","",ROUND((F14*Methodology!$B$10+G14*Methodology!$B$11+H14*Methodology!$B$12+I14*Methodology!$B$13+J14*Methodology!$B$14+K14*Methodology!$B$15)/Methodology!$B$16*Methodology!$B$6,1)) | M14: =IF($A14="","",INDEX(Methodology!$A$20:$A$23,MATCH(L14,Methodology!$B$20:$B$23,1))) | N14: =IF($A14="","",IFERROR(INDEX(Assessment_Results!$C$6:$C$15,MATCH($A14,Assessment_Results!$A$6:$A$15,0)),"")) | O14: =IF($A14="","",IFERROR(INDEX(Assessment_Results!$E$6:$E$15,MATCH($A14,Assessment_Results!$A$6:$A$15,0)),"")) | P14: =IF(OR($A14="",N14=""),"",ROUND(L14*(1-N14*Methodology!$B$5),1)) | Q14: =IF(P14="","",INDEX(Methodology!$A$20:$A$23,MATCH(P14,Methodology!$C$20:$C$23,1))) | R14: =IF($A14="","",IF(N14="","Assessment pending",IF(O14>0,"Remediate critical gaps before approval",IF(Q14="Critical","Escalate: executive risk acceptance required",IF(Q14="High","Conditional approval with remediation plan",IF(Q14="Medium","Approve with standard monitoring","Approve")))))) | S14: =IF($A14="","",IF(Q14="","Pending assessment",INDEX(Approval_Workflow!$B$20:$B$23,MATCH(Q14,Approval_Workflow!$A$20:$A$23,0)))) | V14: =IF($A14="","",INDEX(Methodology!$D$20:$D$23,MATCH(M14,Methodology!$A$20:$A$23,0))) | W14: =IF(OR($A14="",U14=""),"",EDATE(U14,V14)) | X14: =IF(W14="","",IF(W14<Methodology!$B$4,"Overdue",IF(W14-Methodology!$B$4<=90,"Due within 90 days","On schedule")))
L15: =IF($A15="","",ROUND((F15*Methodology!$B$10+G15*Methodology!$B$11+H15*Methodology!$B$12+I15*Methodology!$B$13+J15*Methodology!$B$14+K15*Methodology!$B$15)/Methodology!$B$16*Methodology!$B$6,1)) | M15: =IF($A15="","",INDEX(Methodology!$A$20:$A$23,MATCH(L15,Methodology!$B$20:$B$23,1))) | N15: =IF($A15="","",IFERROR(INDEX(Assessment_Results!$C$6:$C$15,MATCH($A15,Assessment_Results!$A$6:$A$15,0)),"")) | O15: =IF($A15="","",IFERROR(INDEX(Assessment_Results!$E$6:$E$15,MATCH($A15,Assessment_Results!$A$6:$A$15,0)),"")) | P15: =IF(OR($A15="",N15=""),"",ROUND(L15*(1-N15*Methodology!$B$5),1)) | Q15: =IF(P15="","",INDEX(Methodology!$A$20:$A$23,MATCH(P15,Methodology!$C$20:$C$23,1))) | R15: =IF($A15="","",IF(N15="","Assessment pending",IF(O15>0,"Remediate critical gaps before approval",IF(Q15="Critical","Escalate: executive risk acceptance required",IF(Q15="High","Conditional approval with remediation plan",IF(Q15="Medium","Approve with standard monitoring","Approve")))))) | S15: =IF($A15="","",IF(Q15="","Pending assessment",INDEX(Approval_Workflow!$B$20:$B$23,MATCH(Q15,Approval_Workflow!$A$20:$A$23,0)))) | V15: =IF($A15="","",INDEX(Methodology!$D$20:$D$23,MATCH(M15,Methodology!$A$20:$A$23,0))) | W15: =IF(OR($A15="",U15=""),"",EDATE(U15,V15)) | X15: =IF(W15="","",IF(W15<Methodology!$B$4,"Overdue",IF(W15-Methodology!$B$4<=90,"Due within 90 days","On schedule")))
A17: Legend: blue text on yellow = input; black = formula. Inherent rating drives review cycle and monitoring tier; residual rating drives the approval authority.

Sheet Methodology
A1: Scoring Methodology & Assumptions
A2: All scoring parameters live here. Blue cells on a yellow fill are editable; every other sheet recalculates from them.
A3: 1. Program parameters
A4: Assessment as-of date | B4: 46320 | C4: Reference date for 'overdue' and 'due soon' flags. Replace with =TODAY() for live tracking.
A5: Maximum risk reduction from controls | B5: 0.7 | C5: Assumption: even perfect vendor controls cannot remove more than 70% of inherent risk (residual risk never reaches zero).
A6: Inherent score scale factor | B6: 20 | C6: Weighted average of factor scores (1–5) × 20 produces a 20–100 inherent risk score.
A8: 2. Inherent risk factors & weights (score each vendor 1–5 per factor)
A9: Factor | B9: Weight | C9: 1 – Minimal | D9: 2 – Low | E9: 3 – Moderate | F9: 4 – High | G9: 5 – Severe
A10: Data sensitivity | B10: 0.3 | C10: No data shared, or public data only | D10: Internal, non-sensitive data | E10: Confidential business data | F10: Personal data (PII) or financial data | G10: Special-category data, PHI, payment card data, credentials or crown-jewel IP at scale
A11: Business criticality | B11: 0.25 | C11: Convenience tool; no impact if unavailable | D11: Minor disruption; manual workaround exists | E11: Degraded operations beyond one business day | F11: Significant revenue or customer impact within hours | G11: Mission-critical; outage stops core service within 4 hours
A12: System / network access | B12: 0.15 | C12: No access to systems or networks | D12: Limited read-only access to non-sensitive systems | E12: Standard user or API access to internal systems | F12: Privileged or integrated access to production systems | G12: Hosts or administers production environment; network-level trust
A13: Regulatory exposure | B13: 0.1 | C13: No regulatory relevance | D13: Minor contractual or policy requirements | E13: General privacy law applies | F13: Regulated data or activity (GDPR, HIPAA, PCI DSS, SOX) | G13: Multiple regimes; high penalties; regulator scrutiny
A14: Substitutability (lock-in) | B14: 0.1 | C14: Many alternatives; switch in under 1 month | D14: Alternatives exist; switch in 1–3 months | E14: Few alternatives; 3–6 months to switch | F14: Very few alternatives; 6+ months to migrate | G14: Sole source or locked in; no practical alternative
A15: AI impact | B15: 0.1 | C15: No AI/ML functionality | D15: Embedded AI for low-risk convenience features | E15: AI informs internal decisions with human review | F15: AI processes sensitive data or shapes customer-facing outcomes | G15: Autonomous or high-impact AI decisions affecting individuals (possible EU AI Act high-risk use)
A16: Total weight (must equal 100%) | B16: =SUM(B10:B15) -> 1 | C16: =IF(ROUND(B16,4)=1,"OK","ERROR: weights must total 100%") -> OK
A18: 3. Rating bands, review cadence & monitoring intervals
A19: Rating | B19: Inherent score ≥ | C19: Residual score ≥ | D19: Full reassessment (months) | E19: Interim check (months; 0 = at renewal) | F19: Treatment
A20: Low | B20: 0 | C20: 0 | D20: 36 | E20: 0 | F20: Streamlined assessment; standard onboarding; monitor at renewal.
A21: Medium | B21: 40 | C21: 25 | D21: 24 | E21: 12 | F21: Full questionnaire; annual attestation; standard monitoring.
A22: High | B22: 60 | C22: 40 | D22: 18 | E22: 6 | F22: Full assessment with evidence validation; semi-annual checks; remediation plan required for gaps.
A23: Critical | B23: 80 | C23: 60 | D23: 12 | E23: 3 | F23: Enhanced due diligence; quarterly checks; executive approval and exit plan required.
A24: Bands must stay in ascending order (Low → Critical). Residual thresholds are lower than inherent thresholds because residual scores are reduced by control effectiveness.
A25: 4. Questionnaire response values
A26: Response | B26: Value | C26: Treatment in scoring
A27: Yes | B27: 1 | C27: Control fully implemented and evidenced
A28: Partial | B28: 0.5 | C28: Partially implemented, planned, or evidence incomplete
A29: No | B29: 0 | C29: Control absent
A30: N/A | B30: Excluded | C30: Not applicable; removed from numerator and denominator
A32: 5. How the scores are calculated
A33: Inherent Risk Score = Σ(factor score × weight) ÷ Σ(weights) × scale factor → range 20–100.
A34: Control Effectiveness (CE) = Σ(question weight × response value) ÷ Σ(question weight of answered, applicable questions) → 0–100%.
A35: Residual Risk Score = Inherent Risk Score × (1 − CE × maximum risk reduction).
A36: Critical controls answered 'No' are counted as critical gaps and block approval until remediated or formally accepted, regardless of the residual score.
A37: Rating = lookup of the score against the band thresholds in section 3.
A39: 6. Risk Register 5×5 scale (likelihood × impact)
A40: Score | B40: Likelihood | C40: Description
A41: 1 | B41: Rare | C41: Less than 5% chance within 12 months
A42: 2 | B42: Unlikely | C42: 5–20% chance within 12 months
A43: 3 | B43: Possible | C43: 20–50% chance within 12 months
A44: 4 | B44: Likely | C44: 50–80% chance within 12 months
...

Sheet Questionnaire
A1: Vendor Security & Risk Questionnaire
A2: Complete one response column per vendor (Yes / Partial / No / N/A). Weighted scoring feeds Assessment_Results. Sample responses are fictional.
I3: Vendor ID → | J3: =IF(Vendor_Register!$A6="","",Vendor_Register!$A6) -> V-001 | K3: =IF(Vendor_Register!$A7="","",Vendor_Register!$A7) -> V-002 | L3: =IF(Vendor_Register!$A8="","",Vendor_Register!$A8) -> V-003 | M3: =IF(Vendor_Register!$A9="","",Vendor_Register!$A9) -> V-004 | N3: =IF(Vendor_Register!$A10="","",Vendor_Register!$A10) -> V-005 | O3: =IF(Vendor_Register!$A11="","",Vendor_Register!$A11) -> V-006 | P3: =IF(Vendor_Register!$A12="","",Vendor_Register!$A12) | Q3: =IF(Vendor_Register!$A13="","",Vendor_Register!$A13) | R3: =IF(Vendor_Register!$A14="","",Vendor_Register!$A14) | S3: =IF(Vendor_Register!$A15="","",Vendor_Register!$A15)
A4: Q ID | B4: Domain | C4: Question | D4: Applies to | E4: Weight (1–3) | F4: Critical control | G4: ISO/IEC 27001:2022 / 42001 reference | H4: NIST CSF 2.0 / AI RMF reference | I4: Evidence expected | J4: =IF(Vendor_Register!$B6="","(unused)",Vendor_Register!$B6) -> Stratus Cloud Infrastructure | K4: =IF(Vendor_Register!$B7="","(unused)",Vendor_Register!$B7) -> NimbusAI Language Platform | L4: =IF(Vendor_Register!$B8="","(unused)",Vendor_Register!$B8) -> Orbit CRM Suite | M4: =IF(Vendor_Register!$B9="","(unused)",Vendor_Register!$B9) -> InsightML Analytics | N4: =IF(Vendor_Register!$B10="","(unused)",Vendor_Register!$B10) -> Cirrus Backup & Recovery | O4: =IF(Vendor_Register!$B11="","(unused)",Vendor_Register!$B11) -> Brightleaf Survey Tool | P4: =IF(Vendor_Register!$B12="","(unused)",Vendor_Register!$B12) -> (unused) | Q4: =IF(Vendor_Register!$B13="","(unused)",Vendor_Register!$B13) -> (unused) | R4: =IF(Vendor_Register!$B14="","(unused)",Vendor_Register!$B14) -> (unused) | S4: =IF(Vendor_Register!$B15="","(unused)",Vendor_Register!$B15) -> (unused)
A5: GOV-01 | B5: Governance & Risk Management | C5: Does the vendor maintain a documented information security policy, approved by management and reviewed at least annually? | D5: All | E5: 3 | F5: No | G5: ISO 27001 A.5.1 | H5: CSF GV.PO | I5: Policy document with approval and review history | J5: Yes | K5: Yes | L5: Partial | M5: Yes | N5: Yes | O5: Partial
A6: GOV-02 | B6: Governance & Risk Management | C6: Does the vendor hold a current independent attestation or certification (ISO/IEC 27001 or SOC 2 Type II) covering the in-scope services? | D6: All | E6: 3 | F6: Yes | G6: ISO 27001 Cl. 9.2, A.5.35 | H6: CSF GV.SC-07 | I6: Certificate or SOC 2 report: scope, period, exceptions | J6: Yes | K6: Partial | L6: Yes | M6: Partial | N6: Yes | O6: Partial
A7: GOV-03 | B7: Governance & Risk Management | C7: Is there a named executive accountable for information security (CISO or equivalent) and a dedicated security function? | D7: All | E7: 2 | F7: No | G7: ISO 27001 A.5.2 | H7: CSF GV.RR | I7: Organization chart; security team description | J7: Yes | K7: Yes | L7: No | M7: Partial | N7: Yes | O7: No
A8: GOV-04 | B8: Governance & Risk Management | C8: Does the vendor perform formal information security risk assessments at least annually and track risks to closure? | D8: All | E8: 2 | F8: No | G8: ISO 27001 Cl. 6.1.2 | H8: CSF ID.RA | I8: Risk assessment methodology and sample register | J8: Partial | K8: Yes | L8: Partial | M8: Partial | N8: Partial | O8: No
A9: GOV-05 | B9: Governance & Risk Management | C9: Do all personnel complete security awareness training at onboarding and annually, with background screening where legally permitted? | D9: All | E9: 2 | F9: No | G9: ISO 27001 A.6.1, A.6.3 | H9: CSF PR.AT | I9: Training records; screening policy | J9: Yes | K9: Yes | L9: Partial | M9: Yes | N9: Yes | O9: Yes
A10: IAM-01 | B10: Identity & Access Management | C10: Is multi-factor authentication enforced for all workforce access to in-scope systems and for all privileged or administrative access? | D10: All | E10: 3 | F10: Yes | G10: ISO 27001 A.5.17, A.8.5 | H10: CSF PR.AA | I10: MFA policy; configuration screenshots | J10: Yes | K10: Yes | L10: Yes | M10: Yes | N10: Yes | O10: Yes
A11: IAM-02 | B11: Identity & Access Management | C11: Is access granted on least-privilege, role-based principles with documented approval and reviewed at least quarterly? | D11: All | E11: 2 | F11: No | G11: ISO 27001 A.5.15, A.5.18 | H11: CSF PR.AA | I11: Access control policy; latest access review | J11: Yes | K11: Yes | L11: Partial | M11: Partial | N11: Yes | O11: Partial
A12: IAM-03 | B12: Identity & Access Management | C12: Is privileged access tightly managed (separate admin accounts, PAM or just-in-time access, session logging)? | D12: All | E12: 2 | F12: No | G12: ISO 27001 A.8.2 | H12: CSF PR.AA | I12: PAM tooling evidence; privileged user list | J12: Yes | K12: Partial | L12: No | M12: Partial | N12: Yes | O12: No
A13: IAM-04 | B13: Identity & Access Management | C13: Does the joiner-mover-leaver process revoke access within 24 hours of termination? | D13: All | E13: 2 | F13: No | G13: ISO 27001 A.5.18, A.6.5 | H13: CSF PR.AA | I13: Offboarding procedure; sample tickets | J13: Yes | K13: Yes | L13: Partial | M13: Partial | N13: Yes | O13: Partial
A14: IAM-05 | B14: Identity & Access Management | C14: Does the service support SSO (SAML/OIDC), MFA and role-based access for customer users? | D14: All | E14: 1 | F14: No | G14: ISO 27001 A.5.16, A.8.5 | H14: CSF PR.AA | I14: Product documentation | J14: Yes | K14: Yes | L14: Partial | M14: Yes | N14: Yes | O14: Yes
A15: DAT-01 | B15: Data Protection & Privacy | C15: Is customer data encrypted at rest using industry-standard algorithms (e.g., AES-256)? | D15: All | E15: 3 | F15: Yes | G15: ISO 27001 A.8.24 | H15: CSF PR.DS | I15: Architecture document; encryption configuration | J15: Yes | K15: Yes | L15: Yes | M15: Yes | N15: Yes | O15: Yes
A16: DAT-02 | B16: Data Protection & Privacy | C16: Is customer data encrypted in transit using TLS 1.2 or higher? | D16: All | E16: 3 | F16: Yes | G16: ISO 27001 A.8.24, A.5.14 | H16: CSF PR.DS | I16: TLS configuration; external scan result | J16: Yes | K16: Yes | L16: Yes | M16: Yes | N16: Yes | O16: Yes
... A55: AIG-08 | B55: AI Governance & Model Risk | C55: Is there a defined process for AI incident reporting and customer notification (harmful outputs, model failure, data leakage), including alignment to applicable AI regulation (e.g., EU AI Act)? | D55: AI | E55: 2 | F55: No | G55: ISO 42001 Annex A.8.3, A.8.4 | H55: AI RMF MANAGE 4 | I55: AI incident procedure; regulatory mapping | J55: N/A | K55: No | L55: N/A | M55: No | N55: N/A | O55: N/A
A57: Mappings to ISO/IEC 27001:2022, ISO/IEC 42001:2023, NIST CSF 2.0 and NIST AI RMF 1.0 are indicative and should be validated against the current published standards before use in an audit.
A58: Mark AI-specific questions N/A for vendors without AI functionality. A 'No' on a Critical control is counted as a critical gap in Assessment_Results.

Sheet Assessment_Results
A1: Assessment Results – Control Effectiveness by Vendor
A2: Calculated from the Questionnaire. Domain scores = weighted share of controls implemented (Yes = 1, Partial = 0.5, No = 0; N/A excluded).
A5: Vendor ID | B5: Vendor name | C5: Overall control effectiveness | D5: Questionnaire completion | E5: Critical gaps | F5: Governance & Risk Management | G5: Identity & Access Management | H5: Data Protection & Privacy | I5: Cloud & Infrastructure Security | J5: Application & Vulnerability Management | K5: Logging, Monitoring & Incident Response | L5: Business Continuity & Resilience | M5: Subcontractor & Fourth-Party Management | N5: Legal, Regulatory & Compliance | O5: AI Governance & Model Risk
A6: =IF(Vendor_Register!A6="","",Vendor_Register!A6) -> V-001 | B6: =IF(A6="","",Vendor_Register!B6) -> Stratus Cloud Infrastructure | C6: =IF($A6="","",IFERROR(SUMPRODUCT(Questionnaire!$E$5:$E$55*((Questionnaire!J$5:J$55="Yes")*Methodology!$B$27+(Questionnaire!J$5:J$55="Partial")*Methodology!$B$28+(Questionnaire!J$5:J$55="No")*Methodology!$B$29))/SUMPRODUCT(Questionnaire!$E$5:$E$55*((Questionnaire!J$5:J$55="Yes")+(Questionnaire!J$5:J$55="Partial")+(Questionnaire!J$5:J$55="No"))),"")) -> 0.96153846 | D6: =IF($A6="","",SUMPRODUCT(--(Questionnaire!J$5:J$55<>""))/ROWS(Questionnaire!$A$5:$A$55)) -> 1 | E6: =IF($A6="","",SUMPRODUCT((Questionnaire!$F$5:$F$55="Yes")*(Questionnaire!J$5:J$55="No"))) -> 0 | F6: =IF($A6="","",IFERROR(SUMPRODUCT((Questionnaire!$B$5:$B$55=F$5)*Questionnaire!$E$5:$E$55*((Questionnaire!J$5:J$55="Yes")*Methodology!$B$27+(Questionnaire!J$5:J$55="Partial")*Methodology!$B$28+(Questionnaire!J$5:J$55="No")*Methodology!$B$29))/SUMPRODUCT((Questionnaire!$B$5:$B$55=F$5)*Questionnaire!$E$5:$E$55*((Questionnaire!J$5:J$55="Yes")+(Questionnaire!J$5:J$55="Partial")+(Questionnaire!J$5:J$55="No"))),"N/A")) -> 0.91666667 | G6: =IF($A6="","",IFERROR(SUMPRODUCT((Questionnaire!$B$5:$B$55=G$5)*Questionnaire!$E$5:$E$55*((Questionnaire!J$5:J$55="Yes")*Methodology!$B$27+(Questionnaire!J$5:J$55="Partial")*Methodology!$B$28+(Questionnaire!J$5:J$55="No")*Methodology!$B$29))/SUMPRODUCT((Questionnaire!$B$5:$B$55=G$5)*Questionnaire!$E$5:$E$55*((Questionnaire!J$5:J$55="Yes")+(Questionnaire!J$5:J$55="Partial")+(Questionnaire!J$5:J$55="No"))),"N/A")) -> 1 | H6: =IF($A6="","",IFERROR(SUMPRODUCT((Questionnaire!$B$5:$B$55=H$5)*Questionnaire!$E$5:$E$55*((Questionnaire!J$5:J$55="Yes")*Methodology!$B$27+(Questionnaire!J$5:J$55="Partial")*Methodology!$B$28+(Questionnaire!J$5:J$55="No")*Methodology!$B$29))/SUMPRODUCT((Questionnaire!$B$5:$B$55=H$5)*Questionnaire!$E$5:$E$55*((Questionnaire!J$5:J$55="Yes")+(Questionnaire!J$5:J$55="Partial")+(Questionnaire!J$5:J$55="No"))),"N/A")) -> 0.92857143 | I6: =IF($A6="","",IFERROR(SUMPRODUCT((Questionnaire!$B$5:$B$55=I$5)*Questionnaire!$E$5:$E$55*((Questionnaire!J$5:J$55="Yes")*Methodology!$B$27+(Questionnaire!J$5:J$55="Partial")*Methodology!$B$28+(Questionnaire!J$5:J$55="No")*Methodology!$B$29))/SUMPRODUCT((Questionnaire!$B$5:$B$55=I$5)*Questionnaire!$E$5:$E$55*((Questionnaire!J$5:J$55="Yes")+(Questionnaire!J$5:J$55="Partial")+(Questionnaire!J$5:J$55="No"))),"N/A")) -> 0.94444444 | J6: =IF($A6="","",IFERROR(SUMPRODUCT((Questionnaire!$B$5:$B$55=J$5)*Questionnaire!$E$5:$E$55*((Questionnaire!J$5:J$55="Yes")*Methodology!$B$27+(Questionnaire!J$5:J$55="Partial")*Methodology!$B$28+(Questionnaire!J$5:J$55="No")*Methodology!$B$29))/SUMPRODUCT((Questionnaire!$B$5:$B$55=J$5)*Questionnaire!$E$5:$E$55*((Questionnaire!J$5:J$55="Yes")+(Questionnaire!J$5:J$55="Partial")+(Questionnaire!J$5:J$55="No"))),"N/A")) -> 1 | K6: =IF($A6="","",IFERROR(SUMPRODUCT((Questionnaire!$B$5:$B$55=K$5)*Questionnaire!$E$5:$E$55*((Questionnaire!J$5:J$55="Yes")*Methodology!$B$27+(Questionnaire!J$5:J$55="Partial")*Methodology!$B$28+(Questionnaire!J$5:J$55="No")*Methodology!$B$29))/SUMPRODUCT((Questionnaire!$B$5:$B$55=K$5)*Questionnaire!$E$5:$E$55*((Questionnaire!J$5:J$55="Yes")+(Questionnaire!J$5:J$55="Partial")+(Questionnaire!J$5:J$55="No"))),"N/A")) -> 1 | L6: =IF($A6="","",IFERROR(SUMPRODUCT((Questionnaire!$B$5:$B$55=L$5)*Questionnaire!$E$5:$E$55*((Questionnaire!J$5:J$55="Yes")*Methodology!$B$27+(Questionnaire!J$5:J$55="Partial")*Methodology!$B$28+(Questionnaire!J$5:J$55="No")*Methodology!$B$29))/SUMPRODUCT((Questionnaire!$B$5:$B$55=L$5)*Questionnaire!$E$5:$E$55*((Questionnaire!J$5:J$55="Yes")+(Questionnaire!J$5:J$55="Partial")+(Questionnaire!J$5:J$55="No"))),"N/A")) -> 1 | M6: =IF($A6="","",IFERROR(SUMPRODUCT((Questionnaire!$B$5:$B$55=M$5)*Questionnaire!$E$5:$E$55*((Questionnaire!J$5:J$55="Yes")*Methodology!$B$27+(Questionnaire!J$5:J$55="Partial")*Methodology!$B$28+(Questionnaire!J$5:J$55="No")*Methodology!$B$29))/SUMPRODUCT((Questionnaire!$B$5:$B$55=M$5)*Questionnaire!$E$5:$E$55*((Questionnaire!J$5:J$55="Yes")+(Questionnaire!J$5:J$55="Partial")+(Questionnaire!J$5:J$55="No"))),"N/A")) -> 0.85714286 | N6: =IF($A6="","",IFERROR(SUMPRODUCT((Questionnaire!$B$5:$B$55=N$5)*Questionnaire!$E$5:$E$55*((Questionnaire!J$5:J$55="Yes")*Methodology!$B$27+(Questionnaire!J$5:J$55="Partial")*Methodology!$B$28+(Questionnaire!J$5:J$55="No")*Methodology!$B$29))/SUMPRODUCT((Questionnaire!$B$5:$B$55=N$5)*Questionnaire!$E$5:$E$55*((Questionnaire!J$5:J$55="Yes")+(Questionnaire!J$5:J$55="Partial")+(Questionnaire!J$5:J$55="No"))),"N/A")) -> 1 | O6: =IF($A6="","",IFERROR(SUMPRODUCT((Questionnaire!$B$5:$B$55=O$5)*Questionnaire!$E$5:$E$55*((Questionnaire!J$5:J$55="Yes")*Methodology!$B$27+(Questionnaire!J$5:J$55="Partial")*Methodology!$B$28+(Questionnaire!J$5:J$55="No")*Methodology!$B$29))/SUMPRODUCT((Questionnaire!$B$5:$B$55=O$5)*Questionnaire!$E$5:$E$55*((Questionnaire!J$5:J$55="Yes")+(Questionnaire!J$5:J$55="Partial")+(Questionnaire!J$5:J$55="No"))),"N/A")) -> N/A
A7: =IF(Vendor_Register!A7="","",Vendor_Register!A7) -> V-002 | B7: =IF(A7="","",Vendor_Register!B7) -> NimbusAI Language Platform | C7: =IF($A7="","",IFERROR(SUMPRODUCT(Questionnaire!$E$5:$E$55*((Questionnaire!K$5:K$55="Yes")*Methodology!$B$27+(Questionnaire!K$5:K$55="Partial")*Methodology!$B$28+(Questionnaire!K$5:K$55="No")*Methodology!$B$29))/SUMPRODUCT(Questionnaire!$E$5:$E$55*((Questionnaire!K$5:K$55="Yes")+(Questionnaire!K$5:K$55="Partial")+(Questionnaire!K$5:K$55="No"))),"")) -> 0.81531532 | D7: =IF($A7="","",SUMPRODUCT(--(Questionnaire!K$5:K$55<>""))/ROWS(Questionnaire!$A$5:$A$55)) -> 1 | E7: =IF($A7="","",SUMPRODUCT((Questionnaire!$F$5:$F$55="Yes")*(Questionnaire!K$5:K$55="No"))) -> 1 | F7: =IF($A7="","",IFERROR(SUMPRODUCT((Questionnaire!$B$5:$B$55=F$5)*Questionnaire!$E$5:$E$55*((Questionnaire!K$5:K$55="Yes")*Methodology!$B$27+(Questionnaire!K$5:K$55="Partial")*Methodology!$B$28+(Questionnaire!K$5:K$55="No")*Methodology!$B$29))/SUMPRODUCT((Questionnaire!$B$5:$B$55=F$5)*Questionnaire!$E$5:$E$55*((Questionnaire!K$5:K$55="Yes")+(Questionnaire!K$5:K$55="Partial")+(Questionnaire!K$5:K$55="No"))),"N/A")) -> 0.875 | G7: =IF($A7="","",IFERROR(SUMPRODUCT((Questionnaire!$B$5:$B$55=G$5)*Questionnaire!$E$5:$E$55*((Questionnaire!K$5:K$55="Yes")*Methodology!$B$27+(Questionnaire!K$5:K$55="Partial")*Methodology!$B$28+(Questionnaire!K$5:K$55="No")*Methodology!$B$29))/SUMPRODUCT((Questionnaire!$B$5:$B$55=G$5)*Questionnaire!$E$5:$E$55*((Questionnaire!K$5:K$55="Yes")+(Questionnaire!K$5:K$55="Partial")+(Questionnaire!K$5:K$55="No"))),"N/A")) -> 0.9 | H7: =IF($A7="","",IFERROR(SUMPRODUCT((Questionnaire!$B$5:$B$55=H$5)*Questionnaire!$E$5:$E$55*((Questionnaire!K$5:K$55="Yes")*Methodology!$B$27+(Questionnaire!K$5:K$55="Partial")*Methodology!$B$28+(Questionnaire!K$5:K$55="No")*Methodology!$B$29))/SUMPRODUCT((Questionnaire!$B$5:$B$55=H$5)*Questionnaire!$E$5:$E$55*((Questionnaire!K$5:K$55="Yes")+(Questionnaire!K$5:K$55="Partial")+(Questionnaire!K$5:K$55="No"))),"N/A")) -> 0.92857143 | I7: =IF($A7="","",IFERROR(SUMPRODUCT((Questionnaire!$B$5:$B$55=I$5)*Questionnaire!$E$5:$E$55*((Questionnaire!K$5:K$55="Yes")*Methodology!$B$27+(Questionnaire!K$5:K$55="Partial")*Methodology!$B$28+(Questionnaire!K$5:K$55="No")*Methodology!$B$29))/SUMPRODUCT((Questionnaire!$B$5:$B$55=I$5)*Questionnaire!$E$5:$E$55*((Questionnaire!K$5:K$55="Yes")+(Questionnaire!K$5:K$55="Partial")+(Questionnaire!K$5:K$55="No"))),"N/A")) -> 1 | J7: =IF($A7="","",IFERROR(SUMPRODUCT((Questionnaire!$B$5:$B$55=J$5)*Questionnaire!$E$5:$E$55*((Questionnaire!K$5:K$55="Yes")*Methodology!$B$27+(Questionnaire!K$5:K$55="Partial")*Methodology!$B$28+(Questionnaire!K$5:K$55="No")*Methodology!$B$29))/SUMPRODUCT((Questionnaire!$B$5:$B$55=J$5)*Questionnaire!$E$5:$E$55*((Questionnaire!K$5:K$55="Yes")+(Questionnaire!K$5:K$55="Partial")+(Questionnaire!K$5:K$55="No"))),"N/A")) -> 0.875 | K7: =IF($A7="","",IFERROR(SUMPRODUCT((Questionnaire!$B$5:$B$55=K$5)*Questionnaire!$E$5:$E$55*((Questionnaire!K$5:K$55="Yes")*Methodology!$B$27+(Questionnaire!K$5:K$55="Partial")*Methodology!$B$28+(Questionnaire!K$5:K$55="No")*Methodology!$B$29))/SUMPRODUCT((Questionnaire!$B$5:$B$55=K$5)*Questionnaire!$E$5:$E$55*((Questionnaire!K$5:K$55="Yes")+(Questionnaire!K$5:K$55="Partial")+(Questionnaire!K$5:K$55="No"))),"N/A")) -> 0.86363636 | L7: =IF($A7="","",IFERROR(SUMPRODUCT((Questionnaire!$B$5:$B$55=L$5)*Questionnaire!$E$5:$E$55*((Questionnaire!K$5:K$55="Yes")*Methodology!$B$27+(Questionnaire!K$5:K$55="Partial")*Methodology!$B$28+(Questionnaire!K$5:K$55="No")*Methodology!$B$29))/SUMPRODUCT((Questionnaire!$B$5:$B$55=L$5)*Questionnaire!$E$5:$E$55*((Questionnaire!K$5:K$55="Yes")+(Questionnaire!K$5:K$55="Partial")+(Questionnaire!K$5:K$55="No"))),"N/A")) -> 0.875 | M7: =IF($A7="","",IFERROR(SUMPRODUCT((Questionnaire!$B$5:$B$55=M$5)*Questionnaire!$E$5:$E$55*((Questionnaire!K$5:K$55="Yes")*Methodology!$B$27+(Questionnaire!K$5:K$55="Partial")*Methodology!$B$28+(Questionnaire!K$5:K$55="No")*Methodology!$B$29))/SUMPRODUCT((Questionnaire!$B$5:$B$55=M$5)*Questionnaire!$E$5:$E$55*((Questionnaire!K$5:K$55="Yes")+(Questionnaire!K$5:K$55="Partial")+(Questionnaire!K$5:K$55="No"))),"N/A")) -> 0.78571429 | N7: =IF($A7="","",IFERROR(SUMPRODUCT((Questionnaire!$B$5:$B$55=N$5)*Questionnaire!$E$5:$E$55*((Questionnaire!K$5:K$55="Yes")*Methodology!$B$27+(Questionnaire!K$5:K$55="Partial")*Methodology!$B$28+(Questionnaire!K$5:K$55="No")*Methodology!$B$29))/SUMPRODUCT((Questionnaire!$B$5:$B$55=N$5)*Questionnaire!$E$5:$E$55*((Questionnaire!K$5:K$55="Yes")+(Questionnaire!K$5:K$55="Partial")+(Questionnaire!K$5:K$55="No"))),"N/A")) -> 0.875 | O7: =IF($A7="","",IFERROR(SUMPRODUCT((Questionnaire!$B$5:$B$55=O$5)*Questionnaire!$E$5:$E$55*((Questionnaire!K$5:K$55="Yes")*Methodology!$B$27+(Questionnaire!K$5:K$55="Partial")*Methodology!$B$28+(Questionnaire!K$5:K$55="No")*Methodology!$B$29))/SUMPRODUCT((Questionnaire!$B$5:$B$55=O$5)*Questionnaire!$E$5:$E$55*((Questionnaire!K$5:K$55="Yes")+(Questionnaire!K$5:K$55="Partial")+(Questionnaire!K$5:K$55="No"))),"N/A")) -> 0.475
A8: =IF(Vendor_Register!A8="","",Vendor_Register!A8) -> V-003 | B8: =IF(A8="","",Vendor_Register!B8) -> Orbit CRM Suite | C8: =IF($A8="","",IFERROR(SUMPRODUCT(Questionnaire!$E$5:$E$55*((Questionnaire!L$5:L$55="Yes")*Methodology!$B$27+(Questionnaire!L$5:L$55="Partial")*Methodology!$B$28+(Questionnaire!L$5:L$55="No")*Methodology!$B$29))/SUMPRODUCT(Questionnaire!$E$5:$E$55*((Questionnaire!L$5:L$55="Yes")+(Questionnaire!L$5:L$55="Partial")+(Questionnaire!L$5:L$55="No"))),"")) -> 0.51098901 | D8: =IF($A8="","",SUMPRODUCT(--(Questionnaire!L$5:L$55<>""))/ROWS(Questionnaire!$A$5:$A$55)) -> 1 | E8: =IF($A8="","",SUMPRODUCT((Questionnaire!$F$5:$F$55="Yes")*(Questionnaire!L$5:L$55="No"))) -> 0 | F8: =IF($A8="","",IFERROR(SUMPRODUCT((Questionnaire!$B$5:$B$55=F$5)*Questionnaire!$E$5:$E$55*((Questionnaire!L$5:L$55="Yes")*Methodology!$B$27+(Questionnaire!L$5:L$55="Partial")*Methodology!$B$28+(Questionnaire!L$5:L$55="No")*Methodology!$B$29))/SUMPRODUCT((Questionnaire!$B$5:$B$55=F$5)*Questionnaire!$E$5:$E$55*((Questionnaire!L$5:L$55="Yes")+(Questionnaire!L$5:L$55="Partial")+(Questionnaire!L$5:L$55="No"))),"N/A")) -> 0.54166667 | G8: =IF($A8="","",IFERROR(SUMPRODUCT((Questionnaire!$B$5:$B$55=G$5)*Questionnaire!$E$5:$E$55*((Questionnaire!L$5:L$55="Yes")*Methodology!$B$27+(Questionnaire!L$5:L$55="Partial")*Methodology!$B$28+(Questionnaire!L$5:L$55="No")*Methodology!$B$29))/SUMPRODUCT((Questionnaire!$B$5:$B$55=G$5)*Questionnaire!$E$5:$E$55*((Questionnaire!L$5:L$55="Yes")+(Questionnaire!L$5:L$55="Partial")+(Questionnaire!L$5:L$55="No"))),"N/A")) -> 0.55 | H8: =IF($A8="","",IFERROR(SUMPRODUCT((Questionnaire!$B$5:$B$55=H$5)*Questionnaire!$E$5:$E$55*((Questionnaire!L$5:L$55="Yes")*Methodology!$B$27+(Questionnaire!L$5:L$55="Partial")*Methodology!$B$28+(Questionnaire!L$5:L$55="No")*Methodology!$B$29))/SUMPRODUCT((Questionnaire!$B$5:$B$55=H$5)*Questionnaire!$E$5:$E$55*((Questionnaire!L$5:L$55="Yes")+(Questionnaire!L$5:L$55="Partial")+(Questionnaire!L$5:L$55="No"))),"N/A")) -> 0.57142857 | I8: =IF($A8="","",IFERROR(SUMPRODUCT((Questionnaire!$B$5:$B$55=I$5)*Questionnaire!$E$5:$E$55*((Questionnaire!L$5:L$55="Yes")*Methodology!$B$27+(Questionnaire!L$5:L$55="Partial")*Methodology!$B$28+(Questionnaire!L$5:L$55="No")*Methodology!$B$29))/SUMPRODUCT((Questionnaire!$B$5:$B$55=I$5)*Questionnaire!$E$5:$E$55*((Questionnaire!L$5:L$55="Yes")+(Questionnaire!L$5:L$55="Partial")+(Questionnaire!L$5:L$55="No"))),"N/A")) -> 0.66666667 | J8: =IF($A8="","",IFERROR(SUMPRODUCT((Questionnaire!$B$5:$B$55=J$5)*Questionnaire!$E$5:$E$55*((Questionnaire!L$5:L$55="Yes")*Methodology!$B$27+(Questionnaire!L$5:L$55="Partial")*Methodology!$B$28+(Questionnaire!L$5:L$55="No")*Methodology!$B$29))/SUMPRODUCT((Questionnaire!$B$5:$B$55=J$5)*Questionnaire!$E$5:$E$55*((Questionnaire!L$5:L$55="Yes")+(Questionnaire!L$5:L$55="Partial")+(Questionnaire!L$5:L$55="No"))),"N/A")) -> 0.29166667 | K8: =IF($A8="","",IFERROR(SUMPRODUCT((Questionnaire!$B$5:$B$55=K$5)*Questionnaire!$E$5:$E$55*((Questionnaire!L$5:L$55="Yes")*Methodology!$B$27+(Questionnaire!L$5:L$55="Partial")*Methodology!$B$28+(Questionnaire!L$5:L$55="No")*Methodology!$B$29))/SUMPRODUCT((Questionnaire!$B$5:$B$55=K$5)*Questionnaire!$E$5:$E$55*((Questionnaire!L$5:L$55="Yes")+(Questionnaire!L$5:L$55="Partial")+(Questionnaire!L$5:L$55="No"))),"N/A")) -> 0.45454545 | L8: =IF($A8="","",IFERROR(SUMPRODUCT((Questionnaire!$B$5:$B$55=L$5)*Questionnaire!$E$5:$E$55*((Questionnaire!L$5:L$55="Yes")*Methodology!$B$27+(Questionnaire!L$5:L$55="Partial")*Methodology!$B$28+(Questionnaire!L$5:L$55="No")*Methodology!$B$29))/SUMPRODUCT((Questionnaire!$B$5:$B$55=L$5)*Questionnaire!$E$5:$E$55*((Questionnaire!L$5:L$55="Yes")+(Questionnaire!L$5:L$55="Partial")+(Questionnaire!L$5:L$55="No"))),"N/A")) -> 0.375 | M8: =IF($A8="","",IFERROR(SUMPRODUCT((Questionnaire!$B$5:$B$55=M$5)*Questionnaire!$E$5:$E$55*((Questionnaire!L$5:L$55="Yes")*Methodology!$B$27+(Questionnaire!L$5:L$55="Partial")*Methodology!$B$28+(Questionnaire!L$5:L$55="No")*Methodology!$B$29))/SUMPRODUCT((Questionnaire!$B$5:$B$55=M$5)*Questionnaire!$E$5:$E$55*((Questionnaire!L$5:L$55="Yes")+(Questionnaire!L$5:L$55="Partial")+(Questionnaire!L$5:L$55="No"))),"N/A")) -> 0.42857143 | N8: =IF($A8="","",IFERROR(SUMPRODUCT((Questionnaire!$B$5:$B$55=N$5)*Questionnaire!$E$5:$E$55*((Questionnaire!L$5:L$55="Yes")*Methodology!$B$27+(Questionnaire!L$5:L$55="Partial")*Methodology!$B$28+(Questionnaire!L$5:L$55="No")*Methodology!$B$29))/SUMPRODUCT((Questionnaire!$B$5:$B$55=N$5)*Questionnaire!$E$5:$E$55*((Questionnaire!L$5:L$55="Yes")+(Questionnaire!L$5:L$55="Partial")+(Questionnaire!L$5:L$55="No"))),"N/A")) -> 0.75 | O8: =IF($A8="","",IFERROR(SUMPRODUCT((Questionnaire!$B$5:$B$55=O$5)*Questionnaire!$E$5:$E$55*((Questionnaire!L$5:L$55="Yes")*Methodology!$B$27+(Questionnaire!L$5:L$55="Partial")*Methodology!$B$28+(Questionnaire!L$5:L$55="No")*Methodology!$B$29))/SUMPRODUCT((Questionnaire!$B$5:$B$55=O$5)*Questionnaire!$E$5:$E$55*((Questionnaire!L$5:L$55="Yes")+(Questionnaire!L$5:L$55="Partial")+(Questionnaire!L$5:L$55="No"))),"N/A")) -> N/A
